<?xml version="1.0" ?>
<robot xmlns:xacro="http://www.ros.org/wiki/xacro" name="turtlebot3_burger">

  <!-- Define reusable properties -->
  <xacro:property name="wheel_radius" value="0.033"/>
  <xacro:property name="wheel_thickness" value="0.018"/>
  <xacro:property name="base_length" value="0.140"/>
  <xacro:property name="base_height" value="0.143"/>
  <xacro:property name="imu_position" value="-0.032 0 0.068"/>
  <xacro:property name="lidar_position" value="-0.032 0 0.172"/>
  <xacro:property name="caster_position" value="-0.081 0 -0.004"/>
  <xacro:property name="base_color" value="light_black"/>
  <xacro:property name="wheel_color" value="dark"/>

  <!-- Define colors -->
  <material name="black">
      <color rgba="0.0 0.0 0.0 1.0"/>
  </material>
  <material name="dark">
      <color rgba="0.3 0.3 0.3 1.0"/>
  </material>
  <material name="light_black">
      <color rgba="0.4 0.4 0.4 1.0"/>
  </material>
  <material name="blue">
      <color rgba="0.0 0.0 0.8 1.0"/>
  </material>
  <material name="green">
      <color rgba="0.0 0.8 0.0 1.0"/>
  </material>
  <material name="grey">
      <color rgba="0.5 0.5 0.5 1.0"/>
  </material>
  <material name="orange">
      <color rgba="1.0 0.4235 0.0392 1.0"/>
  </material>
  <material name="brown">
      <color rgba="0.8706 0.8118 0.7647 1.0"/>
  </material>
  <material name="red">
      <color rgba="0.8 0.0 0.0 1.0"/>
  </material>
  <material name="white">
      <color rgba="1.0 1.0 1.0 1.0"/>
  </material>

  <!-- Base -->
  <link name="base_footprint"/>
  <joint name="base_joint" type="fixed">
    <parent link="base_footprint"/>
    <child link="base_link"/>
    <origin xyz="0.0 0.0 0.010" rpy="0 0 0"/>
  </joint>
  <link name="base_link">
    <visual>
      <origin xyz="-0.032 0 0.0" rpy="0 0 0"/>
      <geometry>
        <mesh filename="package://turtlebot3_description/meshes/bases/burger_base.stl" scale="0.001 0.001 0.001"/>
      </geometry>
      <material name="${base_color}"/>
    </visual>
    <collision>
      <origin xyz="-0.032 0 0.070" rpy="0 0 0"/>
      <geometry>
        <box size="${base_length} ${base_length} ${base_height}"/>
      </geometry>
    </collision>
    <inertial>
      <origin xyz="0 0 0" rpy="0 0 0"/>
      <mass value="0.82573504"/>
      <inertia ixx="2.2124416e-03" ixy="-1.2294101e-05" ixz="3.4938785e-05" iyy="2.1193702e-03" iyz="-5.0120904e-06" izz="2.0064271e-03"/>
    </inertial>
  </link>

  <!-- Wheels -->
  <joint name="wheel_left_joint" type="continuous">
    <parent link="base_link"/>
    <child link="wheel_left_link"/>
    <origin xyz="0.0 0.08 ${wheel_radius}" rpy="-1.57 0 0"/>
    <axis xyz="0 0 1"/>
  </joint>
  <link name="wheel_left_link">
    <visual>
      <origin xyz="0 0 0" rpy="1.57 0 0"/>
      <geometry>
        <mesh filename="package://turtlebot3_description/meshes/wheels/left_tire.stl" scale="0.001 0.001 0.001"/>
      </geometry>
      <material name="${wheel_color}"/>
    </visual>
    <collision>
      <origin xyz="0 0 0" rpy="0 0 0"/>
      <geometry>
        <cylinder length="${wheel_thickness}" radius="${wheel_radius}"/>
      </geometry>
    </collision>
    <inertial>
      <origin xyz="0 0 0"/>
      <mass value="0.02849894"/>
      <inertia ixx="1.1175580e-05" ixy="-4.2369783e-11" ixz="-5.9381719e-09" iyy="1.1192413e-05" iyz="-1.4400107e-11" izz="2.0712558e-05"/>
    </inertial>
  </link>
  <joint name="wheel_right_joint" type="continuous">
    <parent link="base_link"/>
    <child link="wheel_right_link"/>
    <origin xyz="0.0 -0.08 ${wheel_radius}" rpy="-1.57 0 0"/>
    <axis xyz="0 0 1"/>
  </joint>
  <link name="wheel_right_link">
    <visual>
      <origin xyz="0 0 0" rpy="1.57 0 0"/>
      <geometry>
        <mesh filename="package://turtlebot3_description/meshes/wheels/right_tire.stl" scale="0.001 0.001 0.001"/>
      </geometry>
      <material name="${wheel_color}"/>
    </visual>
    <collision>
      <origin xyz="0 0 0" rpy="0 0 0"/>
      <geometry>
        <cylinder length="${wheel_thickness}" radius="${wheel_radius}"/>
      </geometry>
    </collision>
    <inertial>
      <origin xyz="0 0 0"/>
      <mass value="0.02849894"/>
      <inertia ixx="1.1175580e-05" ixy="-4.2369783e-11" ixz="-5.9381719e-09" iyy="1.1192413e-05" iyz="-1.4400107e-11" izz="2.0712558e-05"/>
    </inertial>
  </link>

  <!-- Back Caster -->
  <joint name="caster_back_joint" type="fixed">
    <parent link="base_link"/>
    <child link="caster_back_link"/>
    <origin xyz="${caster_position}" rpy="-1.57 0 0"/>
  </joint>
  <link name="caster_back_link">
    <collision>
      <origin xyz="0 0.001 0" rpy="0 0 0"/>
      <geometry>
        <box size="0.030 0.009 0.020"/>
      </geometry>
    </collision>
    <inertial>
      <origin xyz="0 0 0"/>
      <mass value="0.005"/>
      <inertia ixx="0.001" ixy="0.0" ixz="0.0" iyy="0.001" iyz="0.0" izz="0.001"/>
    </inertial>
  </link>

  <!-- IMU -->
  <joint name="imu_joint" type="fixed">
    <parent link="base_link"/>
    <child link="imu_link"/>
    <origin xyz="${imu_position}" rpy="0 0 0"/>
  </joint>
  <link name="imu_link"/>

  <!-- LIDAR -->
  <joint name="scan_joint" type="fixed">
    <parent link="base_link"/>
    <child link="base_scan"/>
    <origin xyz="${lidar_position}" rpy="0 0 0"/>
  </joint>
  <link name="base_scan">
    <visual>
      <origin xyz="0 0 0.0" rpy="0 0 0"/>
      <geometry>
        <mesh filename="package://turtlebot3_description/meshes/sensors/lds.stl" scale="0.001 0.001 0.001"/>
      </geometry>
      <material name="${wheel_color}"/>
    </visual>
    <collision>
      <origin xyz="0.015 0 -0.0065" rpy="0 0 0"/>
      <geometry>
        <cylinder length="0.0315" radius="0.055"/>
      </geometry>
    </collision>
    <inertial>
      <mass value="0.114"/>
      <origin xyz="0 0 0"/>
      <inertia ixx="0.001" ixy="0.0" ixz="0.0" iyy="0.001" iyz="0.0" izz="0.001"/>
    </inertial>
  </link>

</robot>
